Exception in thread django-main-thread:
Traceback (most recent call last):
  File "C:\Python313\Lib\threading.py", line 1041, in _bootstrap_inner
    self.run()
    ~~~~~~~~^^
  File "C:\Python313\Lib\threading.py", line 992, in run
    self._target(*self._args, **self._kwargs)
    ~~~~~~~~~~~~^^^^^^^^^^^^^^^^^^^^^^^^^^^^^
  File "C:\Python313\Lib\site-packages\django\utils\autoreload.py", line 64, in wrapper
    fn(*args, **kwargs)
    ~~^^^^^^^^^^^^^^^^^
  File "C:\Python313\Lib\site-packages\django\core\management\commands\runserver.py", line 133, in inner_run
    self.check(display_num_errors=True)
    ~~~~~~~~~~^^^^^^^^^^^^^^^^^^^^^^^^^
  File "C:\Python313\Lib\site-packages\django\core\management\base.py", line 485, in check
    all_issues = checks.run_checks(
        app_configs=app_configs,
    ...<2 lines>...
        databases=databases,
    )
  File "C:\Python313\Lib\site-packages\django\core\checks\registry.py", line 88, in run_checks
    new_errors = check(app_configs=app_configs, databases=databases)
  File "C:\Python313\Lib\site-packages\django\core\checks\urls.py", line 14, in check_url_config
    return check_resolver(resolver)
  File "C:\Python313\Lib\site-packages\django\core\checks\urls.py", line 24, in check_resolver
    return check_method()
  File "C:\Python313\Lib\site-packages\django\urls\resolvers.py", line 494, in check
    for pattern in self.url_patterns:
                   ^^^^^^^^^^^^^^^^^
  File "C:\Python313\Lib\site-packages\django\utils\functional.py", line 57, in __get__
    res = instance.__dict__[self.name] = self.func(instance)
                                         ~~~~~~~~~^^^^^^^^^^
  File "C:\Python313\Lib\site-packages\django\urls\resolvers.py", line 715, in url_patterns
    patterns = getattr(self.urlconf_module, "urlpatterns", self.urlconf_module)
                       ^^^^^^^^^^^^^^^^^^^
  File "C:\Python313\Lib\site-packages\django\utils\functional.py", line 57, in __get__
    res = instance.__dict__[self.name] = self.func(instance)
                                         ~~~~~~~~~^^^^^^^^^^
  File "C:\Python313\Lib\site-packages\django\urls\resolvers.py", line 708, in urlconf_module
    return import_module(self.urlconf_name)
  File "C:\Python313\Lib\importlib\__init__.py", line 88, in import_module
    return _bootstrap._gcd_import(name[level:], package, level)
           ~~~~~~~~~~~~~~~~~~~~~~^^^^^^^^^^^^^^^^^^^^^^^^^^^^^^
  File "<frozen importlib._bootstrap>", line 1387, in _gcd_import
  File "<frozen importlib._bootstrap>", line 1360, in _find_and_load
  File "<frozen importlib._bootstrap>", line 1331, in _find_and_load_unlocked
  File "<frozen importlib._bootstrap>", line 935, in _load_unlocked
  File "<frozen importlib._bootstrap_external>", line 1022, in exec_module
  File "<frozen importlib._bootstrap>", line 488, in _call_with_frames_removed
  File "C:\inetpub\wwwroot\ScriptRepo\ScriptRepo\ScriptRepo\urls.py", line 42, in <module>
    urlpatterns += url(r'^media/(?P<path>.*)$', serve, {'document_root': settings.MEDIA_ROOT}),
                   ^^^
NameError: name 'url' is not defined
Performing system checks...

[16/Nov/2024 09:14:04] "GET /ScriptRepository/polls/ HTTP/1.1" 404 179
[16/Nov/2024 09:14:04] "GET /ScriptRepository/ HTTP/1.1" 200 8228
[16/Nov/2024 09:14:04] "GET /ScriptRepository/ HTTP/1.1" 200 8100
[16/Nov/2024 09:14:04] "GET /ScriptRepository/ HTTP/1.1" 200 8100
[16/Nov/2024 09:14:04] "GET /ScriptRepository/ HTTP/1.1" 200 8228
[16/Nov/2024 09:14:04,333] - Broken pipe from ('127.0.0.1', 50093)
[16/Nov/2024 09:14:04] "GET /ScriptRepository/ HTTP/1.1" 200 8100
[16/Nov/2024 09:14:04,335] - Broken pipe from ('127.0.0.1', 50096)
[16/Nov/2024 09:14:04] "GET /ScriptRepository/ HTTP/1.1" 200 8228
[16/Nov/2024 09:14:04] "GET /ScriptRepository/media/ironman_uRnpcaC.jfif HTTP/1.1" 404 179
[16/Nov/2024 09:14:04] "GET /ScriptRepository/media/ironman_bTPkIFZ.jfif HTTP/1.1" 404 179
[16/Nov/2024 09:14:04] "GET /ScriptRepository/media/ironman_uRnpcaC.jfif HTTP/1.1" 404 179
[16/Nov/2024 09:14:04] "GET /ScriptRepository/media/ironman_bTPkIFZ.jfif HTTP/1.1" 404 179
Performing system checks...

System check identified no issues (0 silenced).
November 16, 2024 - 09:14:04
Django version 4.2.16, using settings 'ScriptRepo.settings'
Starting development server at http://127.0.0.1:26546/
Quit the server with CTRL-BREAK.

[16/Nov/2024 09:14:42] "GET /ScriptRepository/ HTTP/1.1" 200 8100
[16/Nov/2024 09:14:44] "GET /ScriptRepository/media/ironman_uRnpcaC.jfif HTTP/1.1" 404 179
[16/Nov/2024 09:14:44] "GET /ScriptRepository/media/ironman_bTPkIFZ.jfif HTTP/1.1" 404 179
[16/Nov/2024 09:14:46] "GET /ScriptRepository/ HTTP/1.1" 200 8100
[16/Nov/2024 09:14:46] "GET /ScriptRepository/media/ironman_uRnpcaC.jfif HTTP/1.1" 404 179
[16/Nov/2024 09:14:46] "GET /ScriptRepository/media/ironman_bTPkIFZ.jfif HTTP/1.1" 404 179
Performing system checks...

System check identified no issues (0 silenced).
November 16, 2024 - 09:14:40
Django version 4.2.16, using settings 'ScriptRepo.settings'
Starting development server at http://127.0.0.1:26546/
Quit the server with CTRL-BREAK.

Exception in thread django-main-thread:
Traceback (most recent call last):
  File "C:\Python313\Lib\threading.py", line 1041, in _bootstrap_inner
    self.run()
    ~~~~~~~~^^
  File "C:\Python313\Lib\threading.py", line 992, in run
    self._target(*self._args, **self._kwargs)
    ~~~~~~~~~~~~^^^^^^^^^^^^^^^^^^^^^^^^^^^^^
  File "C:\Python313\Lib\site-packages\django\utils\autoreload.py", line 64, in wrapper
    fn(*args, **kwargs)
    ~~^^^^^^^^^^^^^^^^^
  File "C:\Python313\Lib\site-packages\django\core\management\commands\runserver.py", line 133, in inner_run
    self.check(display_num_errors=True)
    ~~~~~~~~~~^^^^^^^^^^^^^^^^^^^^^^^^^
  File "C:\Python313\Lib\site-packages\django\core\management\base.py", line 485, in check
    all_issues = checks.run_checks(
        app_configs=app_configs,
    ...<2 lines>...
        databases=databases,
    )
  File "C:\Python313\Lib\site-packages\django\core\checks\registry.py", line 88, in run_checks
    new_errors = check(app_configs=app_configs, databases=databases)
  File "C:\Python313\Lib\site-packages\django\core\checks\urls.py", line 14, in check_url_config
    return check_resolver(resolver)
  File "C:\Python313\Lib\site-packages\django\core\checks\urls.py", line 24, in check_resolver
    return check_method()
  File "C:\Python313\Lib\site-packages\django\urls\resolvers.py", line 494, in check
    for pattern in self.url_patterns:
                   ^^^^^^^^^^^^^^^^^
  File "C:\Python313\Lib\site-packages\django\utils\functional.py", line 57, in __get__
    res = instance.__dict__[self.name] = self.func(instance)
                                         ~~~~~~~~~^^^^^^^^^^
  File "C:\Python313\Lib\site-packages\django\urls\resolvers.py", line 715, in url_patterns
    patterns = getattr(self.urlconf_module, "urlpatterns", self.urlconf_module)
                       ^^^^^^^^^^^^^^^^^^^
  File "C:\Python313\Lib\site-packages\django\utils\functional.py", line 57, in __get__
    res = instance.__dict__[self.name] = self.func(instance)
                                         ~~~~~~~~~^^^^^^^^^^
  File "C:\Python313\Lib\site-packages\django\urls\resolvers.py", line 708, in urlconf_module
    return import_module(self.urlconf_name)
  File "C:\Python313\Lib\importlib\__init__.py", line 88, in import_module
    return _bootstrap._gcd_import(name[level:], package, level)
           ~~~~~~~~~~~~~~~~~~~~~~^^^^^^^^^^^^^^^^^^^^^^^^^^^^^^
  File "<frozen importlib._bootstrap>", line 1387, in _gcd_import
  File "<frozen importlib._bootstrap>", line 1360, in _find_and_load
  File "<frozen importlib._bootstrap>", line 1331, in _find_and_load_unlocked
  File "<frozen importlib._bootstrap>", line 935, in _load_unlocked
  File "<frozen importlib._bootstrap_external>", line 1018, in exec_module
  File "<frozen importlib._bootstrap_external>", line 1156, in get_code
  File "<frozen importlib._bootstrap_external>", line 1086, in source_to_code
  File "<frozen importlib._bootstrap>", line 488, in _call_with_frames_removed
  File "C:\inetpub\wwwroot\ScriptRepo\ScriptRepo\ScriptRepo\urls.py", line 40
    urlpatterns += static(settings.MEDIA_URL, document_root=settings.MEDIA_ROOT)
    ^^^^^^^^^^^
IndentationError: expected an indented block after 'if' statement on line 39
Performing system checks...

[16/Nov/2024 09:15:13] "GET /ScriptRepository/ HTTP/1.1" 200 8100
[16/Nov/2024 09:15:13] "GET /ScriptRepository/media/ironman_bTPkIFZ.jfif HTTP/1.1" 404 179
[16/Nov/2024 09:15:13] "GET /ScriptRepository/media/ironman_uRnpcaC.jfif HTTP/1.1" 404 179
Performing system checks...

System check identified no issues (0 silenced).
November 16, 2024 - 09:15:12
Django version 4.2.16, using settings 'ScriptRepo.settings'
Starting development server at http://127.0.0.1:26546/
Quit the server with CTRL-BREAK.

Exception in thread django-main-thread:
Traceback (most recent call last):
  File "C:\Python313\Lib\threading.py", line 1041, in _bootstrap_inner
    self.run()
    ~~~~~~~~^^
  File "C:\Python313\Lib\threading.py", line 992, in run
    self._target(*self._args, **self._kwargs)
    ~~~~~~~~~~~~^^^^^^^^^^^^^^^^^^^^^^^^^^^^^
  File "C:\Python313\Lib\site-packages\django\utils\autoreload.py", line 64, in wrapper
    fn(*args, **kwargs)
    ~~^^^^^^^^^^^^^^^^^
  File "C:\Python313\Lib\site-packages\django\core\management\commands\runserver.py", line 133, in inner_run
    self.check(display_num_errors=True)
    ~~~~~~~~~~^^^^^^^^^^^^^^^^^^^^^^^^^
  File "C:\Python313\Lib\site-packages\django\core\management\base.py", line 485, in check
    all_issues = checks.run_checks(
        app_configs=app_configs,
    ...<2 lines>...
        databases=databases,
    )
  File "C:\Python313\Lib\site-packages\django\core\checks\registry.py", line 88, in run_checks
    new_errors = check(app_configs=app_configs, databases=databases)
  File "C:\Python313\Lib\site-packages\django\core\checks\urls.py", line 14, in check_url_config
    return check_resolver(resolver)
  File "C:\Python313\Lib\site-packages\django\core\checks\urls.py", line 24, in check_resolver
    return check_method()
  File "C:\Python313\Lib\site-packages\django\urls\resolvers.py", line 494, in check
    for pattern in self.url_patterns:
                   ^^^^^^^^^^^^^^^^^
  File "C:\Python313\Lib\site-packages\django\utils\functional.py", line 57, in __get__
    res = instance.__dict__[self.name] = self.func(instance)
                                         ~~~~~~~~~^^^^^^^^^^
  File "C:\Python313\Lib\site-packages\django\urls\resolvers.py", line 715, in url_patterns
    patterns = getattr(self.urlconf_module, "urlpatterns", self.urlconf_module)
                       ^^^^^^^^^^^^^^^^^^^
  File "C:\Python313\Lib\site-packages\django\utils\functional.py", line 57, in __get__
    res = instance.__dict__[self.name] = self.func(instance)
                                         ~~~~~~~~~^^^^^^^^^^
  File "C:\Python313\Lib\site-packages\django\urls\resolvers.py", line 708, in urlconf_module
    return import_module(self.urlconf_name)
  File "C:\Python313\Lib\importlib\__init__.py", line 88, in import_module
    return _bootstrap._gcd_import(name[level:], package, level)
           ~~~~~~~~~~~~~~~~~~~~~~^^^^^^^^^^^^^^^^^^^^^^^^^^^^^^
  File "<frozen importlib._bootstrap>", line 1387, in _gcd_import
  File "<frozen importlib._bootstrap>", line 1360, in _find_and_load
  File "<frozen importlib._bootstrap>", line 1331, in _find_and_load_unlocked
  File "<frozen importlib._bootstrap>", line 935, in _load_unlocked
  File "<frozen importlib._bootstrap_external>", line 1018, in exec_module
  File "<frozen importlib._bootstrap_external>", line 1156, in get_code
  File "<frozen importlib._bootstrap_external>", line 1086, in source_to_code
  File "<frozen importlib._bootstrap>", line 488, in _call_with_frames_removed
  File "C:\inetpub\wwwroot\ScriptRepo\ScriptRepo\ScriptRepo\urls.py", line 40
    urlpatterns += static(settings.MEDIA_URL, document_root=settings.MEDIA_ROOT)
    ^^^^^^^^^^^
IndentationError: expected an indented block after 'if' statement on line 39
Performing system checks...

[16/Nov/2024 09:15:38] "GET /ScriptRepository/ HTTP/1.1" 200 8100
[16/Nov/2024 09:15:38] "GET /ScriptRepository/media/ironman_uRnpcaC.jfif HTTP/1.1" 404 179
[16/Nov/2024 09:15:38] "GET /ScriptRepository/media/ironman_bTPkIFZ.jfif HTTP/1.1" 404 179
Performing system checks...

System check identified no issues (0 silenced).
November 16, 2024 - 09:15:31
Django version 4.2.16, using settings 'ScriptRepo.settings'
Starting development server at http://127.0.0.1:26546/
Quit the server with CTRL-BREAK.

Exception in thread django-main-thread:
Traceback (most recent call last):
  File "C:\Python313\Lib\threading.py", line 1041, in _bootstrap_inner
    self.run()
    ~~~~~~~~^^
  File "C:\Python313\Lib\threading.py", line 992, in run
    self._target(*self._args, **self._kwargs)
    ~~~~~~~~~~~~^^^^^^^^^^^^^^^^^^^^^^^^^^^^^
  File "C:\Python313\Lib\site-packages\django\utils\autoreload.py", line 64, in wrapper
    fn(*args, **kwargs)
    ~~^^^^^^^^^^^^^^^^^
  File "C:\Python313\Lib\site-packages\django\core\management\commands\runserver.py", line 133, in inner_run
    self.check(display_num_errors=True)
    ~~~~~~~~~~^^^^^^^^^^^^^^^^^^^^^^^^^
  File "C:\Python313\Lib\site-packages\django\core\management\base.py", line 485, in check
    all_issues = checks.run_checks(
        app_configs=app_configs,
    ...<2 lines>...
        databases=databases,
    )
  File "C:\Python313\Lib\site-packages\django\core\checks\registry.py", line 88, in run_checks
    new_errors = check(app_configs=app_configs, databases=databases)
  File "C:\Python313\Lib\site-packages\django\core\checks\urls.py", line 14, in check_url_config
    return check_resolver(resolver)
  File "C:\Python313\Lib\site-packages\django\core\checks\urls.py", line 24, in check_resolver
    return check_method()
  File "C:\Python313\Lib\site-packages\django\urls\resolvers.py", line 494, in check
    for pattern in self.url_patterns:
                   ^^^^^^^^^^^^^^^^^
  File "C:\Python313\Lib\site-packages\django\utils\functional.py", line 57, in __get__
    res = instance.__dict__[self.name] = self.func(instance)
                                         ~~~~~~~~~^^^^^^^^^^
  File "C:\Python313\Lib\site-packages\django\urls\resolvers.py", line 715, in url_patterns
    patterns = getattr(self.urlconf_module, "urlpatterns", self.urlconf_module)
                       ^^^^^^^^^^^^^^^^^^^
  File "C:\Python313\Lib\site-packages\django\utils\functional.py", line 57, in __get__
    res = instance.__dict__[self.name] = self.func(instance)
                                         ~~~~~~~~~^^^^^^^^^^
  File "C:\Python313\Lib\site-packages\django\urls\resolvers.py", line 708, in urlconf_module
    return import_module(self.urlconf_name)
  File "C:\Python313\Lib\importlib\__init__.py", line 88, in import_module
    return _bootstrap._gcd_import(name[level:], package, level)
           ~~~~~~~~~~~~~~~~~~~~~~^^^^^^^^^^^^^^^^^^^^^^^^^^^^^^
  File "<frozen importlib._bootstrap>", line 1387, in _gcd_import
  File "<frozen importlib._bootstrap>", line 1360, in _find_and_load
  File "<frozen importlib._bootstrap>", line 1331, in _find_and_load_unlocked
  File "<frozen importlib._bootstrap>", line 935, in _load_unlocked
  File "<frozen importlib._bootstrap_external>", line 1022, in exec_module
  File "<frozen importlib._bootstrap>", line 488, in _call_with_frames_removed
  File "C:\inetpub\wwwroot\ScriptRepo\ScriptRepo\ScriptRepo\urls.py", line 26, in <module>
    from django.conf.urls import url
ImportError: cannot import name 'url' from 'django.conf.urls' (C:\Python313\Lib\site-packages\django\conf\urls\__init__.py). Did you mean: 'urls'?
Performing system checks...

Exception in thread django-main-thread:
Traceback (most recent call last):
  File "C:\Python313\Lib\threading.py", line 1041, in _bootstrap_inner
    self.run()
    ~~~~~~~~^^
  File "C:\Python313\Lib\threading.py", line 992, in run
    self._target(*self._args, **self._kwargs)
    ~~~~~~~~~~~~^^^^^^^^^^^^^^^^^^^^^^^^^^^^^
  File "C:\Python313\Lib\site-packages\django\utils\autoreload.py", line 64, in wrapper
    fn(*args, **kwargs)
    ~~^^^^^^^^^^^^^^^^^
  File "C:\Python313\Lib\site-packages\django\core\management\commands\runserver.py", line 133, in inner_run
    self.check(display_num_errors=True)
    ~~~~~~~~~~^^^^^^^^^^^^^^^^^^^^^^^^^
  File "C:\Python313\Lib\site-packages\django\core\management\base.py", line 485, in check
    all_issues = checks.run_checks(
        app_configs=app_configs,
    ...<2 lines>...
        databases=databases,
    )
  File "C:\Python313\Lib\site-packages\django\core\checks\registry.py", line 88, in run_checks
    new_errors = check(app_configs=app_configs, databases=databases)
  File "C:\Python313\Lib\site-packages\django\core\checks\urls.py", line 14, in check_url_config
    return check_resolver(resolver)
  File "C:\Python313\Lib\site-packages\django\core\checks\urls.py", line 24, in check_resolver
    return check_method()
  File "C:\Python313\Lib\site-packages\django\urls\resolvers.py", line 494, in check
    for pattern in self.url_patterns:
                   ^^^^^^^^^^^^^^^^^
  File "C:\Python313\Lib\site-packages\django\utils\functional.py", line 57, in __get__
    res = instance.__dict__[self.name] = self.func(instance)
                                         ~~~~~~~~~^^^^^^^^^^
  File "C:\Python313\Lib\site-packages\django\urls\resolvers.py", line 715, in url_patterns
    patterns = getattr(self.urlconf_module, "urlpatterns", self.urlconf_module)
                       ^^^^^^^^^^^^^^^^^^^
  File "C:\Python313\Lib\site-packages\django\utils\functional.py", line 57, in __get__
    res = instance.__dict__[self.name] = self.func(instance)
                                         ~~~~~~~~~^^^^^^^^^^
  File "C:\Python313\Lib\site-packages\django\urls\resolvers.py", line 708, in urlconf_module
    return import_module(self.urlconf_name)
  File "C:\Python313\Lib\importlib\__init__.py", line 88, in import_module
    return _bootstrap._gcd_import(name[level:], package, level)
           ~~~~~~~~~~~~~~~~~~~~~~^^^^^^^^^^^^^^^^^^^^^^^^^^^^^^
  File "<frozen importlib._bootstrap>", line 1387, in _gcd_import
  File "<frozen importlib._bootstrap>", line 1360, in _find_and_load
  File "<frozen importlib._bootstrap>", line 1331, in _find_and_load_unlocked
  File "<frozen importlib._bootstrap>", line 935, in _load_unlocked
  File "<frozen importlib._bootstrap_external>", line 1022, in exec_module
  File "<frozen importlib._bootstrap>", line 488, in _call_with_frames_removed
  File "C:\inetpub\wwwroot\ScriptRepo\ScriptRepo\ScriptRepo\urls.py", line 26, in <module>
    from django.conf.urls import url
ImportError: cannot import name 'url' from 'django.conf.urls' (C:\Python313\Lib\site-packages\django\conf\urls\__init__.py). Did you mean: 'urls'?
Performing system checks...

Exception in thread django-main-thread:
Traceback (most recent call last):
  File "C:\Python313\Lib\threading.py", line 1041, in _bootstrap_inner
    self.run()
    ~~~~~~~~^^
  File "C:\Python313\Lib\threading.py", line 992, in run
    self._target(*self._args, **self._kwargs)
    ~~~~~~~~~~~~^^^^^^^^^^^^^^^^^^^^^^^^^^^^^
  File "C:\Python313\Lib\site-packages\django\utils\autoreload.py", line 64, in wrapper
    fn(*args, **kwargs)
    ~~^^^^^^^^^^^^^^^^^
  File "C:\Python313\Lib\site-packages\django\core\management\commands\runserver.py", line 133, in inner_run
    self.check(display_num_errors=True)
    ~~~~~~~~~~^^^^^^^^^^^^^^^^^^^^^^^^^
  File "C:\Python313\Lib\site-packages\django\core\management\base.py", line 485, in check
    all_issues = checks.run_checks(
        app_configs=app_configs,
    ...<2 lines>...
        databases=databases,
    )
  File "C:\Python313\Lib\site-packages\django\core\checks\registry.py", line 88, in run_checks
    new_errors = check(app_configs=app_configs, databases=databases)
  File "C:\Python313\Lib\site-packages\django\core\checks\urls.py", line 14, in check_url_config
    return check_resolver(resolver)
  File "C:\Python313\Lib\site-packages\django\core\checks\urls.py", line 24, in check_resolver
    return check_method()
  File "C:\Python313\Lib\site-packages\django\urls\resolvers.py", line 494, in check
    for pattern in self.url_patterns:
                   ^^^^^^^^^^^^^^^^^
  File "C:\Python313\Lib\site-packages\django\utils\functional.py", line 57, in __get__
    res = instance.__dict__[self.name] = self.func(instance)
                                         ~~~~~~~~~^^^^^^^^^^
  File "C:\Python313\Lib\site-packages\django\urls\resolvers.py", line 715, in url_patterns
    patterns = getattr(self.urlconf_module, "urlpatterns", self.urlconf_module)
                       ^^^^^^^^^^^^^^^^^^^
  File "C:\Python313\Lib\site-packages\django\utils\functional.py", line 57, in __get__
    res = instance.__dict__[self.name] = self.func(instance)
                                         ~~~~~~~~~^^^^^^^^^^
  File "C:\Python313\Lib\site-packages\django\urls\resolvers.py", line 708, in urlconf_module
    return import_module(self.urlconf_name)
  File "C:\Python313\Lib\importlib\__init__.py", line 88, in import_module
    return _bootstrap._gcd_import(name[level:], package, level)
           ~~~~~~~~~~~~~~~~~~~~~~^^^^^^^^^^^^^^^^^^^^^^^^^^^^^^
  File "<frozen importlib._bootstrap>", line 1387, in _gcd_import
  File "<frozen importlib._bootstrap>", line 1360, in _find_and_load
  File "<frozen importlib._bootstrap>", line 1331, in _find_and_load_unlocked
  File "<frozen importlib._bootstrap>", line 935, in _load_unlocked
  File "<frozen importlib._bootstrap_external>", line 1022, in exec_module
  File "<frozen importlib._bootstrap>", line 488, in _call_with_frames_removed
  File "C:\inetpub\wwwroot\ScriptRepo\ScriptRepo\ScriptRepo\urls.py", line 26, in <module>
    from django.conf.urls import URLs
ImportError: cannot import name 'URLs' from 'django.conf.urls' (C:\Python313\Lib\site-packages\django\conf\urls\__init__.py). Did you mean: 'urls'?
Performing system checks...

Exception in thread django-main-thread:
Traceback (most recent call last):
  File "C:\Python313\Lib\threading.py", line 1041, in _bootstrap_inner
    self.run()
    ~~~~~~~~^^
  File "C:\Python313\Lib\threading.py", line 992, in run
    self._target(*self._args, **self._kwargs)
    ~~~~~~~~~~~~^^^^^^^^^^^^^^^^^^^^^^^^^^^^^
  File "C:\Python313\Lib\site-packages\django\utils\autoreload.py", line 64, in wrapper
    fn(*args, **kwargs)
    ~~^^^^^^^^^^^^^^^^^
  File "C:\Python313\Lib\site-packages\django\core\management\commands\runserver.py", line 133, in inner_run
    self.check(display_num_errors=True)
    ~~~~~~~~~~^^^^^^^^^^^^^^^^^^^^^^^^^
  File "C:\Python313\Lib\site-packages\django\core\management\base.py", line 485, in check
    all_issues = checks.run_checks(
        app_configs=app_configs,
    ...<2 lines>...
        databases=databases,
    )
  File "C:\Python313\Lib\site-packages\django\core\checks\registry.py", line 88, in run_checks
    new_errors = check(app_configs=app_configs, databases=databases)
  File "C:\Python313\Lib\site-packages\django\core\checks\urls.py", line 14, in check_url_config
    return check_resolver(resolver)
  File "C:\Python313\Lib\site-packages\django\core\checks\urls.py", line 24, in check_resolver
    return check_method()
  File "C:\Python313\Lib\site-packages\django\urls\resolvers.py", line 494, in check
    for pattern in self.url_patterns:
                   ^^^^^^^^^^^^^^^^^
  File "C:\Python313\Lib\site-packages\django\utils\functional.py", line 57, in __get__
    res = instance.__dict__[self.name] = self.func(instance)
                                         ~~~~~~~~~^^^^^^^^^^
  File "C:\Python313\Lib\site-packages\django\urls\resolvers.py", line 715, in url_patterns
    patterns = getattr(self.urlconf_module, "urlpatterns", self.urlconf_module)
                       ^^^^^^^^^^^^^^^^^^^
  File "C:\Python313\Lib\site-packages\django\utils\functional.py", line 57, in __get__
    res = instance.__dict__[self.name] = self.func(instance)
                                         ~~~~~~~~~^^^^^^^^^^
  File "C:\Python313\Lib\site-packages\django\urls\resolvers.py", line 708, in urlconf_module
    return import_module(self.urlconf_name)
  File "C:\Python313\Lib\importlib\__init__.py", line 88, in import_module
    return _bootstrap._gcd_import(name[level:], package, level)
           ~~~~~~~~~~~~~~~~~~~~~~^^^^^^^^^^^^^^^^^^^^^^^^^^^^^^
  File "<frozen importlib._bootstrap>", line 1387, in _gcd_import
  File "<frozen importlib._bootstrap>", line 1360, in _find_and_load
  File "<frozen importlib._bootstrap>", line 1331, in _find_and_load_unlocked
  File "<frozen importlib._bootstrap>", line 935, in _load_unlocked
  File "<frozen importlib._bootstrap_external>", line 1022, in exec_module
  File "<frozen importlib._bootstrap>", line 488, in _call_with_frames_removed
  File "C:\inetpub\wwwroot\ScriptRepo\ScriptRepo\ScriptRepo\urls.py", line 26, in <module>
    from django.conf.urls import url
ImportError: cannot import name 'url' from 'django.conf.urls' (C:\Python313\Lib\site-packages\django\conf\urls\__init__.py). Did you mean: 'urls'?
Performing system checks...

Exception in thread django-main-thread:
Traceback (most recent call last):
  File "C:\Python313\Lib\threading.py", line 1041, in _bootstrap_inner
    self.run()
    ~~~~~~~~^^
  File "C:\Python313\Lib\threading.py", line 992, in run
    self._target(*self._args, **self._kwargs)
    ~~~~~~~~~~~~^^^^^^^^^^^^^^^^^^^^^^^^^^^^^
  File "C:\Python313\Lib\site-packages\django\utils\autoreload.py", line 64, in wrapper
    fn(*args, **kwargs)
    ~~^^^^^^^^^^^^^^^^^
  File "C:\Python313\Lib\site-packages\django\core\management\commands\runserver.py", line 133, in inner_run
    self.check(display_num_errors=True)
    ~~~~~~~~~~^^^^^^^^^^^^^^^^^^^^^^^^^
  File "C:\Python313\Lib\site-packages\django\core\management\base.py", line 485, in check
    all_issues = checks.run_checks(
        app_configs=app_configs,
    ...<2 lines>...
        databases=databases,
    )
  File "C:\Python313\Lib\site-packages\django\core\checks\registry.py", line 88, in run_checks
    new_errors = check(app_configs=app_configs, databases=databases)
  File "C:\Python313\Lib\site-packages\django\core\checks\urls.py", line 14, in check_url_config
    return check_resolver(resolver)
  File "C:\Python313\Lib\site-packages\django\core\checks\urls.py", line 24, in check_resolver
    return check_method()
  File "C:\Python313\Lib\site-packages\django\urls\resolvers.py", line 494, in check
    for pattern in self.url_patterns:
                   ^^^^^^^^^^^^^^^^^
  File "C:\Python313\Lib\site-packages\django\utils\functional.py", line 57, in __get__
    res = instance.__dict__[self.name] = self.func(instance)
                                         ~~~~~~~~~^^^^^^^^^^
  File "C:\Python313\Lib\site-packages\django\urls\resolvers.py", line 715, in url_patterns
    patterns = getattr(self.urlconf_module, "urlpatterns", self.urlconf_module)
                       ^^^^^^^^^^^^^^^^^^^
  File "C:\Python313\Lib\site-packages\django\utils\functional.py", line 57, in __get__
    res = instance.__dict__[self.name] = self.func(instance)
                                         ~~~~~~~~~^^^^^^^^^^
  File "C:\Python313\Lib\site-packages\django\urls\resolvers.py", line 708, in urlconf_module
    return import_module(self.urlconf_name)
  File "C:\Python313\Lib\importlib\__init__.py", line 88, in import_module
    return _bootstrap._gcd_import(name[level:], package, level)
           ~~~~~~~~~~~~~~~~~~~~~~^^^^^^^^^^^^^^^^^^^^^^^^^^^^^^
  File "<frozen importlib._bootstrap>", line 1387, in _gcd_import
  File "<frozen importlib._bootstrap>", line 1360, in _find_and_load
  File "<frozen importlib._bootstrap>", line 1331, in _find_and_load_unlocked
  File "<frozen importlib._bootstrap>", line 935, in _load_unlocked
  File "<frozen importlib._bootstrap_external>", line 1022, in exec_module
  File "<frozen importlib._bootstrap>", line 488, in _call_with_frames_removed
  File "C:\inetpub\wwwroot\ScriptRepo\ScriptRepo\ScriptRepo\urls.py", line 20, in <module>
    from django.conf.urls import url
ImportError: cannot import name 'url' from 'django.conf.urls' (C:\Python313\Lib\site-packages\django\conf\urls\__init__.py). Did you mean: 'urls'?
Performing system checks...

Exception in thread django-main-thread:
Traceback (most recent call last):
  File "C:\Python313\Lib\threading.py", line 1041, in _bootstrap_inner
    self.run()
    ~~~~~~~~^^
  File "C:\Python313\Lib\threading.py", line 992, in run
    self._target(*self._args, **self._kwargs)
    ~~~~~~~~~~~~^^^^^^^^^^^^^^^^^^^^^^^^^^^^^
  File "C:\Python313\Lib\site-packages\django\utils\autoreload.py", line 64, in wrapper
    fn(*args, **kwargs)
    ~~^^^^^^^^^^^^^^^^^
  File "C:\Python313\Lib\site-packages\django\core\management\commands\runserver.py", line 133, in inner_run
    self.check(display_num_errors=True)
    ~~~~~~~~~~^^^^^^^^^^^^^^^^^^^^^^^^^
  File "C:\Python313\Lib\site-packages\django\core\management\base.py", line 485, in check
    all_issues = checks.run_checks(
        app_configs=app_configs,
    ...<2 lines>...
        databases=databases,
    )
  File "C:\Python313\Lib\site-packages\django\core\checks\registry.py", line 88, in run_checks
    new_errors = check(app_configs=app_configs, databases=databases)
  File "C:\Python313\Lib\site-packages\django\core\checks\urls.py", line 14, in check_url_config
    return check_resolver(resolver)
  File "C:\Python313\Lib\site-packages\django\core\checks\urls.py", line 24, in check_resolver
    return check_method()
  File "C:\Python313\Lib\site-packages\django\urls\resolvers.py", line 494, in check
    for pattern in self.url_patterns:
                   ^^^^^^^^^^^^^^^^^
  File "C:\Python313\Lib\site-packages\django\utils\functional.py", line 57, in __get__
    res = instance.__dict__[self.name] = self.func(instance)
                                         ~~~~~~~~~^^^^^^^^^^
  File "C:\Python313\Lib\site-packages\django\urls\resolvers.py", line 715, in url_patterns
    patterns = getattr(self.urlconf_module, "urlpatterns", self.urlconf_module)
                       ^^^^^^^^^^^^^^^^^^^
  File "C:\Python313\Lib\site-packages\django\utils\functional.py", line 57, in __get__
    res = instance.__dict__[self.name] = self.func(instance)
                                         ~~~~~~~~~^^^^^^^^^^
  File "C:\Python313\Lib\site-packages\django\urls\resolvers.py", line 708, in urlconf_module
    return import_module(self.urlconf_name)
  File "C:\Python313\Lib\importlib\__init__.py", line 88, in import_module
    return _bootstrap._gcd_import(name[level:], package, level)
           ~~~~~~~~~~~~~~~~~~~~~~^^^^^^^^^^^^^^^^^^^^^^^^^^^^^^
  File "<frozen importlib._bootstrap>", line 1387, in _gcd_import
  File "<frozen importlib._bootstrap>", line 1360, in _find_and_load
  File "<frozen importlib._bootstrap>", line 1331, in _find_and_load_unlocked
  File "<frozen importlib._bootstrap>", line 935, in _load_unlocked
  File "<frozen importlib._bootstrap_external>", line 1022, in exec_module
  File "<frozen importlib._bootstrap>", line 488, in _call_with_frames_removed
  File "C:\inetpub\wwwroot\ScriptRepo\ScriptRepo\ScriptRepo\urls.py", line 20, in <module>
    from django.conf.urls import urls
ImportError: cannot import name 'urls' from 'django.conf.urls' (C:\Python313\Lib\site-packages\django\conf\urls\__init__.py)
Performing system checks...

Exception in thread django-main-thread:
Traceback (most recent call last):
  File "C:\Python313\Lib\threading.py", line 1041, in _bootstrap_inner
    self.run()
    ~~~~~~~~^^
  File "C:\Python313\Lib\threading.py", line 992, in run
    self._target(*self._args, **self._kwargs)
    ~~~~~~~~~~~~^^^^^^^^^^^^^^^^^^^^^^^^^^^^^
  File "C:\Python313\Lib\site-packages\django\utils\autoreload.py", line 64, in wrapper
    fn(*args, **kwargs)
    ~~^^^^^^^^^^^^^^^^^
  File "C:\Python313\Lib\site-packages\django\core\management\commands\runserver.py", line 133, in inner_run
    self.check(display_num_errors=True)
    ~~~~~~~~~~^^^^^^^^^^^^^^^^^^^^^^^^^
  File "C:\Python313\Lib\site-packages\django\core\management\base.py", line 485, in check
    all_issues = checks.run_checks(
        app_configs=app_configs,
    ...<2 lines>...
        databases=databases,
    )
  File "C:\Python313\Lib\site-packages\django\core\checks\registry.py", line 88, in run_checks
    new_errors = check(app_configs=app_configs, databases=databases)
  File "C:\Python313\Lib\site-packages\django\core\checks\urls.py", line 14, in check_url_config
    return check_resolver(resolver)
  File "C:\Python313\Lib\site-packages\django\core\checks\urls.py", line 24, in check_resolver
    return check_method()
  File "C:\Python313\Lib\site-packages\django\urls\resolvers.py", line 494, in check
    for pattern in self.url_patterns:
                   ^^^^^^^^^^^^^^^^^
  File "C:\Python313\Lib\site-packages\django\utils\functional.py", line 57, in __get__
    res = instance.__dict__[self.name] = self.func(instance)
                                         ~~~~~~~~~^^^^^^^^^^
  File "C:\Python313\Lib\site-packages\django\urls\resolvers.py", line 715, in url_patterns
    patterns = getattr(self.urlconf_module, "urlpatterns", self.urlconf_module)
                       ^^^^^^^^^^^^^^^^^^^
  File "C:\Python313\Lib\site-packages\django\utils\functional.py", line 57, in __get__
    res = instance.__dict__[self.name] = self.func(instance)
                                         ~~~~~~~~~^^^^^^^^^^
  File "C:\Python313\Lib\site-packages\django\urls\resolvers.py", line 708, in urlconf_module
    return import_module(self.urlconf_name)
  File "C:\Python313\Lib\importlib\__init__.py", line 88, in import_module
    return _bootstrap._gcd_import(name[level:], package, level)
           ~~~~~~~~~~~~~~~~~~~~~~^^^^^^^^^^^^^^^^^^^^^^^^^^^^^^
  File "<frozen importlib._bootstrap>", line 1387, in _gcd_import
  File "<frozen importlib._bootstrap>", line 1360, in _find_and_load
  File "<frozen importlib._bootstrap>", line 1331, in _find_and_load_unlocked
  File "<frozen importlib._bootstrap>", line 935, in _load_unlocked
  File "<frozen importlib._bootstrap_external>", line 1022, in exec_module
  File "<frozen importlib._bootstrap>", line 488, in _call_with_frames_removed
  File "C:\inetpub\wwwroot\ScriptRepo\ScriptRepo\ScriptRepo\urls.py", line 20, in <module>
    from django.conf.urls import urls
ImportError: cannot import name 'urls' from 'django.conf.urls' (C:\Python313\Lib\site-packages\django\conf\urls\__init__.py)
Performing system checks...

Exception in thread django-main-thread:
Traceback (most recent call last):
  File "C:\Python313\Lib\threading.py", line 1041, in _bootstrap_inner
    self.run()
    ~~~~~~~~^^
  File "C:\Python313\Lib\threading.py", line 992, in run
    self._target(*self._args, **self._kwargs)
    ~~~~~~~~~~~~^^^^^^^^^^^^^^^^^^^^^^^^^^^^^
  File "C:\Python313\Lib\site-packages\django\utils\autoreload.py", line 64, in wrapper
    fn(*args, **kwargs)
    ~~^^^^^^^^^^^^^^^^^
  File "C:\Python313\Lib\site-packages\django\core\management\commands\runserver.py", line 133, in inner_run
    self.check(display_num_errors=True)
    ~~~~~~~~~~^^^^^^^^^^^^^^^^^^^^^^^^^
  File "C:\Python313\Lib\site-packages\django\core\management\base.py", line 485, in check
    all_issues = checks.run_checks(
        app_configs=app_configs,
    ...<2 lines>...
        databases=databases,
    )
  File "C:\Python313\Lib\site-packages\django\core\checks\registry.py", line 88, in run_checks
    new_errors = check(app_configs=app_configs, databases=databases)
  File "C:\Python313\Lib\site-packages\django\core\checks\urls.py", line 14, in check_url_config
    return check_resolver(resolver)
  File "C:\Python313\Lib\site-packages\django\core\checks\urls.py", line 24, in check_resolver
    return check_method()
  File "C:\Python313\Lib\site-packages\django\urls\resolvers.py", line 494, in check
    for pattern in self.url_patterns:
                   ^^^^^^^^^^^^^^^^^
  File "C:\Python313\Lib\site-packages\django\utils\functional.py", line 57, in __get__
    res = instance.__dict__[self.name] = self.func(instance)
                                         ~~~~~~~~~^^^^^^^^^^
  File "C:\Python313\Lib\site-packages\django\urls\resolvers.py", line 715, in url_patterns
    patterns = getattr(self.urlconf_module, "urlpatterns", self.urlconf_module)
                       ^^^^^^^^^^^^^^^^^^^
  File "C:\Python313\Lib\site-packages\django\utils\functional.py", line 57, in __get__
    res = instance.__dict__[self.name] = self.func(instance)
                                         ~~~~~~~~~^^^^^^^^^^
  File "C:\Python313\Lib\site-packages\django\urls\resolvers.py", line 708, in urlconf_module
    return import_module(self.urlconf_name)
  File "C:\Python313\Lib\importlib\__init__.py", line 88, in import_module
    return _bootstrap._gcd_import(name[level:], package, level)
           ~~~~~~~~~~~~~~~~~~~~~~^^^^^^^^^^^^^^^^^^^^^^^^^^^^^^
  File "<frozen importlib._bootstrap>", line 1387, in _gcd_import
  File "<frozen importlib._bootstrap>", line 1360, in _find_and_load
  File "<frozen importlib._bootstrap>", line 1331, in _find_and_load_unlocked
  File "<frozen importlib._bootstrap>", line 935, in _load_unlocked
  File "<frozen importlib._bootstrap_external>", line 1022, in exec_module
  File "<frozen importlib._bootstrap>", line 488, in _call_with_frames_removed
  File "C:\inetpub\wwwroot\ScriptRepo\ScriptRepo\ScriptRepo\urls.py", line 20, in <module>
    from django.conf.urls import urls
ImportError: cannot import name 'urls' from 'django.conf.urls' (C:\Python313\Lib\site-packages\django\conf\urls\__init__.py)
Performing system checks...

Exception in thread django-main-thread:
Traceback (most recent call last):
  File "C:\Python313\Lib\threading.py", line 1041, in _bootstrap_inner
    self.run()
    ~~~~~~~~^^
  File "C:\Python313\Lib\threading.py", line 992, in run
    self._target(*self._args, **self._kwargs)
    ~~~~~~~~~~~~^^^^^^^^^^^^^^^^^^^^^^^^^^^^^
  File "C:\Python313\Lib\site-packages\django\utils\autoreload.py", line 64, in wrapper
    fn(*args, **kwargs)
    ~~^^^^^^^^^^^^^^^^^
  File "C:\Python313\Lib\site-packages\django\core\management\commands\runserver.py", line 133, in inner_run
    self.check(display_num_errors=True)
    ~~~~~~~~~~^^^^^^^^^^^^^^^^^^^^^^^^^
  File "C:\Python313\Lib\site-packages\django\core\management\base.py", line 485, in check
    all_issues = checks.run_checks(
        app_configs=app_configs,
    ...<2 lines>...
        databases=databases,
    )
  File "C:\Python313\Lib\site-packages\django\core\checks\registry.py", line 88, in run_checks
    new_errors = check(app_configs=app_configs, databases=databases)
  File "C:\Python313\Lib\site-packages\django\core\checks\urls.py", line 14, in check_url_config
    return check_resolver(resolver)
  File "C:\Python313\Lib\site-packages\django\core\checks\urls.py", line 24, in check_resolver
    return check_method()
  File "C:\Python313\Lib\site-packages\django\urls\resolvers.py", line 494, in check
    for pattern in self.url_patterns:
                   ^^^^^^^^^^^^^^^^^
  File "C:\Python313\Lib\site-packages\django\utils\functional.py", line 57, in __get__
    res = instance.__dict__[self.name] = self.func(instance)
                                         ~~~~~~~~~^^^^^^^^^^
  File "C:\Python313\Lib\site-packages\django\urls\resolvers.py", line 715, in url_patterns
    patterns = getattr(self.urlconf_module, "urlpatterns", self.urlconf_module)
                       ^^^^^^^^^^^^^^^^^^^
  File "C:\Python313\Lib\site-packages\django\utils\functional.py", line 57, in __get__
    res = instance.__dict__[self.name] = self.func(instance)
                                         ~~~~~~~~~^^^^^^^^^^
  File "C:\Python313\Lib\site-packages\django\urls\resolvers.py", line 708, in urlconf_module
    return import_module(self.urlconf_name)
  File "C:\Python313\Lib\importlib\__init__.py", line 88, in import_module
    return _bootstrap._gcd_import(name[level:], package, level)
           ~~~~~~~~~~~~~~~~~~~~~~^^^^^^^^^^^^^^^^^^^^^^^^^^^^^^
  File "<frozen importlib._bootstrap>", line 1387, in _gcd_import
  File "<frozen importlib._bootstrap>", line 1360, in _find_and_load
  File "<frozen importlib._bootstrap>", line 1331, in _find_and_load_unlocked
  File "<frozen importlib._bootstrap>", line 935, in _load_unlocked
  File "<frozen importlib._bootstrap_external>", line 1022, in exec_module
  File "<frozen importlib._bootstrap>", line 488, in _call_with_frames_removed
  File "C:\inetpub\wwwroot\ScriptRepo\ScriptRepo\ScriptRepo\urls.py", line 20, in <module>
    from django.conf.urls import url
ImportError: cannot import name 'url' from 'django.conf.urls' (C:\Python313\Lib\site-packages\django\conf\urls\__init__.py). Did you mean: 'urls'?
Performing system checks...

[16/Nov/2024 09:23:03] "GET /ScriptRepository/ HTTP/1.1" 200 8100
[16/Nov/2024 09:23:03] "GET /ScriptRepository/media/ironman_uRnpcaC.jfif HTTP/1.1" 404 179
[16/Nov/2024 09:23:03] "GET /ScriptRepository/media/ironman_bTPkIFZ.jfif HTTP/1.1" 404 179
[16/Nov/2024 09:23:05] "GET /ScriptRepository/ HTTP/1.1" 200 8100
[16/Nov/2024 09:23:05] "GET /ScriptRepository/media/ironman_uRnpcaC.jfif HTTP/1.1" 404 179
[16/Nov/2024 09:23:05] "GET /ScriptRepository/media/ironman_bTPkIFZ.jfif HTTP/1.1" 404 179
[16/Nov/2024 09:23:06] "GET /ScriptRepository/ HTTP/1.1" 200 8100
[16/Nov/2024 09:23:06] "GET /ScriptRepository/ HTTP/1.1" 200 8100
[16/Nov/2024 09:23:06] "GET /ScriptRepository/ HTTP/1.1" 200 8100
[16/Nov/2024 09:23:07] "GET /ScriptRepository/ HTTP/1.1" 200 8100
[16/Nov/2024 09:23:07] "GET /ScriptRepository/ HTTP/1.1" 200 8100
[16/Nov/2024 09:23:07] "GET /ScriptRepository/media/ironman_uRnpcaC.jfif HTTP/1.1" 404 179
[16/Nov/2024 09:23:07] "GET /ScriptRepository/media/ironman_bTPkIFZ.jfif HTTP/1.1" 404 179
[16/Nov/2024 09:23:08] "GET /ScriptRepository/ HTTP/1.1" 200 8100
[16/Nov/2024 09:23:08] "GET /ScriptRepository/media/ironman_bTPkIFZ.jfif HTTP/1.1" 404 179
[16/Nov/2024 09:23:08] "GET /ScriptRepository/media/ironman_uRnpcaC.jfif HTTP/1.1" 404 179
[16/Nov/2024 09:23:08] "GET /ScriptRepository/ HTTP/1.1" 200 8100
[16/Nov/2024 09:23:09] "GET /ScriptRepository/media/ironman_uRnpcaC.jfif HTTP/1.1" 404 179
[16/Nov/2024 09:23:09] "GET /ScriptRepository/media/ironman_bTPkIFZ.jfif HTTP/1.1" 404 179
[16/Nov/2024 09:23:09] "GET /ScriptRepository/ HTTP/1.1" 200 8100
[16/Nov/2024 09:23:09] "GET /ScriptRepository/media/ironman_uRnpcaC.jfif HTTP/1.1" 404 179
[16/Nov/2024 09:23:09] "GET /ScriptRepository/media/ironman_bTPkIFZ.jfif HTTP/1.1" 404 179
Performing system checks...

System check identified no issues (0 silenced).
November 16, 2024 - 09:22:56
Django version 4.2.16, using settings 'ScriptRepo.settings'
Starting development server at http://127.0.0.1:26546/
Quit the server with CTRL-BREAK.

Performing system checks...

System check identified no issues (0 silenced).
November 16, 2024 - 09:23:26
Django version 4.2.16, using settings 'ScriptRepo.settings'
Starting development server at http://127.0.0.1:26546/
Quit the server with CTRL-BREAK.

[16/Nov/2024 09:25:06] "GET /ScriptRepository/ HTTP/1.1" 200 8100
[16/Nov/2024 09:25:07] "GET /ScriptRepository/media/ironman_uRnpcaC.jfif HTTP/1.1" 404 179
[16/Nov/2024 09:25:07] "GET /ScriptRepository/media/ironman_bTPkIFZ.jfif HTTP/1.1" 404 179
[16/Nov/2024 09:25:09] "GET /ScriptRepository/ HTTP/1.1" 200 8100
[16/Nov/2024 09:25:09] "GET /ScriptRepository/media/ironman_bTPkIFZ.jfif HTTP/1.1" 404 179
[16/Nov/2024 09:25:09] "GET /ScriptRepository/media/ironman_uRnpcaC.jfif HTTP/1.1" 404 179
[16/Nov/2024 09:25:11] "GET /ScriptRepository/login/ HTTP/1.1" 200 5517
[16/Nov/2024 09:25:20] "POST /ScriptRepository/login/ HTTP/1.1" 302 0
[16/Nov/2024 09:25:20] "GET /ScriptRepository/ HTTP/1.1" 200 8228
[16/Nov/2024 09:25:20] "GET /ScriptRepository/media/ironman_bTPkIFZ.jfif HTTP/1.1" 404 179
[16/Nov/2024 09:25:20] "GET /ScriptRepository/media/ironman_uRnpcaC.jfif HTTP/1.1" 404 179
[16/Nov/2024 09:25:22] "GET /ScriptRepository/profile/ HTTP/1.1" 200 6168
[16/Nov/2024 09:25:23] "GET /ScriptRepository/media/ironman_bTPkIFZ.jfif HTTP/1.1" 404 179
[16/Nov/2024 09:25:31] "POST /ScriptRepository/profile/ HTTP/1.1" 302 0
[16/Nov/2024 09:25:31] "GET /ScriptRepository/profile/ HTTP/1.1" 200 6372
[16/Nov/2024 09:25:31] "GET /ScriptRepository/media/profile_pics/ironman.jfif HTTP/1.1" 404 179
[16/Nov/2024 09:25:34] "GET /ScriptRepository/profile/ HTTP/1.1" 200 6183
[16/Nov/2024 09:25:34] "GET /ScriptRepository/media/profile_pics/ironman.jfif HTTP/1.1" 404 179
[16/Nov/2024 09:25:37] "GET /ScriptRepository/ HTTP/1.1" 200 8248
[16/Nov/2024 09:25:37] "GET /ScriptRepository/media/ironman_uRnpcaC.jfif HTTP/1.1" 404 179
[16/Nov/2024 09:25:37] "GET /ScriptRepository/media/profile_pics/ironman.jfif HTTP/1.1" 404 179
[16/Nov/2024 09:25:41] "GET /ScriptRepository/post/55/ HTTP/1.1" 200 5109
[16/Nov/2024 09:25:41] "GET /ScriptRepository/media/profile_pics/ironman.jfif HTTP/1.1" 404 179
[16/Nov/2024 09:25:43] "GET /ScriptRepository/post/55/delete/ HTTP/1.1" 200 4798
[16/Nov/2024 09:25:44] "POST /ScriptRepository/post/55/delete/ HTTP/1.1" 302 0
[16/Nov/2024 09:25:44] "GET /ScriptRepository HTTP/1.1" 301 0
[16/Nov/2024 09:25:45] "GET /ScriptRepository/ HTTP/1.1" 200 7408
[16/Nov/2024 09:25:45] "GET /ScriptRepository/media/profile_pics/ironman.jfif HTTP/1.1" 404 179
[16/Nov/2024 09:25:45] "GET /ScriptRepository/media/ironman_uRnpcaC.jfif HTTP/1.1" 404 179
[16/Nov/2024 09:25:51] "GET /ScriptRepository/admin/ HTTP/1.1" 200 9940
[16/Nov/2024 09:25:51] "GET /ScriptRepository/static/admin/css/base.css HTTP/1.1" 304 0
[16/Nov/2024 09:25:51] "GET /ScriptRepository/static/admin/css/dark_mode.css HTTP/1.1" 304 0
[16/Nov/2024 09:25:51] "GET /ScriptRepository/static/admin/js/theme.js HTTP/1.1" 304 0
[16/Nov/2024 09:25:51] "GET /ScriptRepository/static/admin/css/responsive.css HTTP/1.1" 304 0
[16/Nov/2024 09:25:51] "GET /ScriptRepository/static/admin/css/dashboard.css HTTP/1.1" 304 0
[16/Nov/2024 09:25:51] "GET /ScriptRepository/static/admin/js/nav_sidebar.js HTTP/1.1" 304 0
[16/Nov/2024 09:25:51] "GET /ScriptRepository/static/admin/css/nav_sidebar.css HTTP/1.1" 304 0
[16/Nov/2024 09:25:52] "GET /ScriptRepository/static/admin/img/icon-changelink.svg HTTP/1.1" 304 0
[16/Nov/2024 09:25:52] "GET /ScriptRepository/static/admin/img/icon-deletelink.svg HTTP/1.1" 304 0
[16/Nov/2024 09:25:52] "GET /ScriptRepository/static/admin/img/icon-addlink.svg HTTP/1.1" 304 0
[16/Nov/2024 09:25:56] "POST /ScriptRepository/admin/logout/ HTTP/1.1" 200 3729
[16/Nov/2024 09:26:00] "GET /ScriptRepository/admin/ HTTP/1.1" 302 0
[16/Nov/2024 09:26:01] "GET /ScriptRepository/admin/login/?next=/ScriptRepository/admin/ HTTP/1.1" 200 4368
[16/Nov/2024 09:26:01] "GET /ScriptRepository/static/admin/css/login.css HTTP/1.1" 304 0
[16/Nov/2024 09:26:06] "GET /ScriptRepository/ HTTP/1.1" 200 7280
[16/Nov/2024 09:26:07] "GET /ScriptRepository/media/profile_pics/ironman.jfif HTTP/1.1" 404 179
[16/Nov/2024 09:26:07] "GET /ScriptRepository/media/ironman_uRnpcaC.jfif HTTP/1.1" 404 179
Performing system checks...

System check identified no issues (0 silenced).
November 16, 2024 - 09:25:05
Django version 4.2.16, using settings 'ScriptRepo.settings'
Starting development server at http://127.0.0.1:26546/
Quit the server with CTRL-BREAK.

Performing system checks...

System check identified no issues (0 silenced).
November 16, 2024 - 09:26:44
Django version 4.2.16, using settings 'ScriptRepo.settings'
Starting development server at http://127.0.0.1:26546/
Quit the server with CTRL-BREAK.

Performing system checks...

System check identified no issues (0 silenced).
November 16, 2024 - 09:27:28
Django version 4.2.16, using settings 'ScriptRepo.settings'
Starting development server at http://127.0.0.1:26546/
Quit the server with CTRL-BREAK.

Watching for file changes with StatReloader
[16/Nov/2024 09:27:37] "GET /ScriptRepository/ HTTP/1.1" 200 7280
Not Found: /ScriptRepository/media/profile_pics/ironman.jfif
[16/Nov/2024 09:27:38] "GET /ScriptRepository/media/profile_pics/ironman.jfif HTTP/1.1" 404 5032
Not Found: /ScriptRepository/media/ironman_uRnpcaC.jfif
[16/Nov/2024 09:27:38] "GET /ScriptRepository/media/ironman_uRnpcaC.jfif HTTP/1.1" 404 5017
[16/Nov/2024 09:27:39] "GET /ScriptRepository/ HTTP/1.1" 200 7280
Not Found: /ScriptRepository/media/ironman_uRnpcaC.jfif
[16/Nov/2024 09:27:40] "GET /ScriptRepository/media/ironman_uRnpcaC.jfif HTTP/1.1" 404 5017
Not Found: /ScriptRepository/media/profile_pics/ironman.jfif
[16/Nov/2024 09:27:40] "GET /ScriptRepository/media/profile_pics/ironman.jfif HTTP/1.1" 404 5032
[16/Nov/2024 09:27:41] "GET /ScriptRepository/ HTTP/1.1" 200 7280
Not Found: /ScriptRepository/media/profile_pics/ironman.jfif
[16/Nov/2024 09:27:41] "GET /ScriptRepository/media/profile_pics/ironman.jfif HTTP/1.1" 404 5032
Not Found: /ScriptRepository/media/ironman_uRnpcaC.jfif
[16/Nov/2024 09:27:41] "GET /ScriptRepository/media/ironman_uRnpcaC.jfif HTTP/1.1" 404 5017
[16/Nov/2024 09:27:42] "GET /ScriptRepository/ HTTP/1.1" 200 7280
Not Found: /ScriptRepository/media/profile_pics/ironman.jfif
[16/Nov/2024 09:27:42] "GET /ScriptRepository/media/profile_pics/ironman.jfif HTTP/1.1" 404 5032
Not Found: /ScriptRepository/media/ironman_uRnpcaC.jfif
[16/Nov/2024 09:27:42] "GET /ScriptRepository/media/ironman_uRnpcaC.jfif HTTP/1.1" 404 5017
[16/Nov/2024 09:27:42] "GET /ScriptRepository/ HTTP/1.1" 200 7280
[16/Nov/2024 09:27:42] "GET /ScriptRepository/ HTTP/1.1" 200 7280
[16/Nov/2024 09:27:43] "GET /ScriptRepository/ HTTP/1.1" 200 7280
[16/Nov/2024 09:27:43] "GET /ScriptRepository/ HTTP/1.1" 200 7280
[16/Nov/2024 09:27:43] "GET /ScriptRepository/ HTTP/1.1" 200 7280
[16/Nov/2024 09:27:43] "GET /ScriptRepository/ HTTP/1.1" 200 7280
Not Found: /ScriptRepository/media/ironman_uRnpcaC.jfif
Not Found: /ScriptRepository/media/profile_pics/ironman.jfif
[16/Nov/2024 09:27:44] "GET /ScriptRepository/media/ironman_uRnpcaC.jfif HTTP/1.1" 404 5017
[16/Nov/2024 09:27:44] "GET /ScriptRepository/media/profile_pics/ironman.jfif HTTP/1.1" 404 5032
[16/Nov/2024 09:27:44] "GET /ScriptRepository/ HTTP/1.1" 200 7280
Not Found: /ScriptRepository/media/profile_pics/ironman.jfif
Not Found: /ScriptRepository/media/ironman_uRnpcaC.jfif
[16/Nov/2024 09:27:44] "GET /ScriptRepository/media/ironman_uRnpcaC.jfif HTTP/1.1" 404 5017
[16/Nov/2024 09:27:44] "GET /ScriptRepository/media/profile_pics/ironman.jfif HTTP/1.1" 404 5032
[16/Nov/2024 09:27:47] "GET /ScriptRepository/login/ HTTP/1.1" 200 5517
[16/Nov/2024 09:27:54] "POST /ScriptRepository/login/ HTTP/1.1" 302 0
[16/Nov/2024 09:27:54] "GET /ScriptRepository/ HTTP/1.1" 200 7408
Not Found: /ScriptRepository/media/profile_pics/ironman.jfif
[16/Nov/2024 09:27:54] "GET /ScriptRepository/media/profile_pics/ironman.jfif HTTP/1.1" 404 5032
Not Found: /ScriptRepository/media/ironman_uRnpcaC.jfif
[16/Nov/2024 09:27:54] "GET /ScriptRepository/media/ironman_uRnpcaC.jfif HTTP/1.1" 404 5017
[16/Nov/2024 09:27:57] "GET /ScriptRepository/ HTTP/1.1" 200 7408
Not Found: /ScriptRepository/media/profile_pics/ironman.jfif
Not Found: /ScriptRepository/media/ironman_uRnpcaC.jfif
[16/Nov/2024 09:27:57] "GET /ScriptRepository/media/profile_pics/ironman.jfif HTTP/1.1" 404 5032
[16/Nov/2024 09:27:57] "GET /ScriptRepository/media/ironman_uRnpcaC.jfif HTTP/1.1" 404 5017
[16/Nov/2024 09:27:58] "GET /ScriptRepository/ HTTP/1.1" 200 7408
[16/Nov/2024 09:27:58] "GET /ScriptRepository/ HTTP/1.1" 200 7408
Not Found: /ScriptRepository/media/profile_pics/ironman.jfif
Not Found: /ScriptRepository/media/ironman_uRnpcaC.jfif
[16/Nov/2024 09:27:58] "GET /ScriptRepository/media/profile_pics/ironman.jfif HTTP/1.1" 404 5032
[16/Nov/2024 09:27:58] "GET /ScriptRepository/media/ironman_uRnpcaC.jfif HTTP/1.1" 404 5017
Not Found: /ScriptRepository/media/ironman_uRnpcaC.jfif
[16/Nov/2024 09:28:00] "GET /ScriptRepository/media/ironman_uRnpcaC.jfif HTTP/1.1" 404 5017
[16/Nov/2024 09:28:12] "GET /ScriptRepository/post/60/ HTTP/1.1" 200 5169
Not Found: /ScriptRepository/media/ironman_uRnpcaC.jfif
[16/Nov/2024 09:28:12] "GET /ScriptRepository/media/ironman_uRnpcaC.jfif HTTP/1.1" 404 5017
[16/Nov/2024 09:28:14] "GET /ScriptRepository/post/60/delete/ HTTP/1.1" 200 4847
[16/Nov/2024 09:28:15] "POST /ScriptRepository/post/60/delete/ HTTP/1.1" 302 0
[16/Nov/2024 09:28:16] "GET /ScriptRepository HTTP/1.1" 301 0
[16/Nov/2024 09:28:16] "GET /ScriptRepository/ HTTP/1.1" 200 6508
Not Found: /ScriptRepository/media/profile_pics/ironman.jfif
[16/Nov/2024 09:28:16] "GET /ScriptRepository/media/profile_pics/ironman.jfif HTTP/1.1" 404 5032
[16/Nov/2024 09:28:17] "GET /ScriptRepository/post/59/ HTTP/1.1" 200 5057
Not Found: /ScriptRepository/media/profile_pics/ironman.jfif
[16/Nov/2024 09:28:18] "GET /ScriptRepository/media/profile_pics/ironman.jfif HTTP/1.1" 404 5032
[16/Nov/2024 09:28:18] "GET /ScriptRepository/post/59/delete/ HTTP/1.1" 200 4801
[16/Nov/2024 09:28:19] "POST /ScriptRepository/post/59/delete/ HTTP/1.1" 302 0
[16/Nov/2024 09:28:20] "GET /ScriptRepository HTTP/1.1" 301 0
[16/Nov/2024 09:28:20] "GET /ScriptRepository/ HTTP/1.1" 200 5720
Not Found: /ScriptRepository/media/profile_pics/ironman.jfif
[16/Nov/2024 09:28:20] "GET /ScriptRepository/media/profile_pics/ironman.jfif HTTP/1.1" 404 5032
[16/Nov/2024 09:28:21] "GET /ScriptRepository/post/57/ HTTP/1.1" 200 5053
Not Found: /ScriptRepository/media/profile_pics/ironman.jfif
[16/Nov/2024 09:28:21] "GET /ScriptRepository/media/profile_pics/ironman.jfif HTTP/1.1" 404 5032
[16/Nov/2024 09:28:22] "GET /ScriptRepository/post/57/delete/ HTTP/1.1" 200 4800
[16/Nov/2024 09:28:23] "POST /ScriptRepository/post/57/delete/ HTTP/1.1" 302 0
[16/Nov/2024 09:28:23] "GET /ScriptRepository HTTP/1.1" 301 0
[16/Nov/2024 09:28:23] "GET /ScriptRepository/ HTTP/1.1" 200 4936
Not Found: /ScriptRepository/media/profile_pics/ironman.jfif
[16/Nov/2024 09:28:24] "GET /ScriptRepository/media/profile_pics/ironman.jfif HTTP/1.1" 404 5032
[16/Nov/2024 09:28:25] "GET /ScriptRepository/post/56/ HTTP/1.1" 200 5058
Not Found: /ScriptRepository/media/profile_pics/ironman.jfif
[16/Nov/2024 09:28:25] "GET /ScriptRepository/media/profile_pics/ironman.jfif HTTP/1.1" 404 5032
[16/Nov/2024 09:28:26] "GET /ScriptRepository/post/56/delete/ HTTP/1.1" 200 4803
[16/Nov/2024 09:28:27] "POST /ScriptRepository/post/56/delete/ HTTP/1.1" 302 0
[16/Nov/2024 09:28:27] "GET /ScriptRepository HTTP/1.1" 301 0
[16/Nov/2024 09:28:27] "GET /ScriptRepository/ HTTP/1.1" 200 4147
[16/Nov/2024 09:28:29] "GET /ScriptRepository/post/new/ HTTP/1.1" 200 5499
[16/Nov/2024 09:28:30] "GET /ScriptRepository/profile/ HTTP/1.1" 200 6183
Not Found: /ScriptRepository/media/profile_pics/ironman.jfif
[16/Nov/2024 09:28:30] "GET /ScriptRepository/media/profile_pics/ironman.jfif HTTP/1.1" 404 5032
[16/Nov/2024 09:28:36] "POST /ScriptRepository/profile/ HTTP/1.1" 302 0
[16/Nov/2024 09:28:36] "GET /ScriptRepository/profile/ HTTP/1.1" 200 6396
Not Found: /ScriptRepository/media/profile_pics/ironman_xq2cLIU.jfif
[16/Nov/2024 09:28:37] "GET /ScriptRepository/media/profile_pics/ironman_xq2cLIU.jfif HTTP/1.1" 404 5056
[16/Nov/2024 09:28:39] "GET /ScriptRepository/post/new/ HTTP/1.1" 200 5499
[16/Nov/2024 09:28:43] "POST /ScriptRepository/post/new/ HTTP/1.1" 302 0
[16/Nov/2024 09:28:43] "GET /ScriptRepository/post/61/ HTTP/1.1" 200 5065
Not Found: /ScriptRepository/media/profile_pics/ironman_xq2cLIU.jfif
[16/Nov/2024 09:28:43] "GET /ScriptRepository/media/profile_pics/ironman_xq2cLIU.jfif HTTP/1.1" 404 5056
[16/Nov/2024 09:28:45] "GET /ScriptRepository/ HTTP/1.1" 200 4943
Not Found: /ScriptRepository/media/profile_pics/ironman_xq2cLIU.jfif
[16/Nov/2024 09:28:45] "GET /ScriptRepository/media/profile_pics/ironman_xq2cLIU.jfif HTTP/1.1" 404 5056
Not Found: /ScriptRepository/media/profile_pics/ironman_xq2cLIU.jfif
[16/Nov/2024 09:28:47] "GET /ScriptRepository/media/profile_pics/ironman_xq2cLIU.jfif HTTP/1.1" 404 5056
C:\inetpub\wwwroot\ScriptRepo\ScriptRepo\ScriptRepo\urls.py changed, reloading.
Performing system checks...

System check identified no issues (0 silenced).
November 16, 2024 - 09:27:37
Django version 4.2.16, using settings 'ScriptRepo.settings'
Starting development server at http://127.0.0.1:26546/
Quit the server with CTRL-BREAK.

Watching for file changes with StatReloader
Not Found: /ScriptRepository/media/profile_pics/ironman_xq2cLIU.jfif
[16/Nov/2024 09:29:20] "GET /ScriptRepository/media/profile_pics/ironman_xq2cLIU.jfif HTTP/1.1" 404 4930
[16/Nov/2024 09:29:24] "GET /ScriptRepository/ HTTP/1.1" 200 4943
Not Found: /ScriptRepository/media/profile_pics/ironman_xq2cLIU.jfif
[16/Nov/2024 09:29:25] "GET /ScriptRepository/media/profile_pics/ironman_xq2cLIU.jfif HTTP/1.1" 404 4930
[16/Nov/2024 09:29:25] "GET /ScriptRepository/ HTTP/1.1" 200 4943
[16/Nov/2024 09:29:26] "GET /ScriptRepository/ HTTP/1.1" 200 4943
[16/Nov/2024 09:29:26] "GET /ScriptRepository/ HTTP/1.1" 200 4943
[16/Nov/2024 09:29:26] "GET /ScriptRepository/ HTTP/1.1" 200 4943
Not Found: /ScriptRepository/media/profile_pics/ironman_xq2cLIU.jfif
[16/Nov/2024 09:29:26] "GET /ScriptRepository/media/profile_pics/ironman_xq2cLIU.jfif HTTP/1.1" 404 4930
[16/Nov/2024 09:29:27] "GET /ScriptRepository/ HTTP/1.1" 200 4943
Not Found: /ScriptRepository/media/profile_pics/ironman_xq2cLIU.jfif
[16/Nov/2024 09:29:27] "GET /ScriptRepository/media/profile_pics/ironman_xq2cLIU.jfif HTTP/1.1" 404 4930
[16/Nov/2024 09:29:29] "GET /ScriptRepository/ HTTP/1.1" 200 4943
Not Found: /ScriptRepository/media/profile_pics/ironman_xq2cLIU.jfif
[16/Nov/2024 09:29:29] "GET /ScriptRepository/media/profile_pics/ironman_xq2cLIU.jfif HTTP/1.1" 404 4930
C:\inetpub\wwwroot\ScriptRepo\ScriptRepo\ScriptRepo\urls.py changed, reloading.
Performing system checks...

System check identified no issues (0 silenced).
November 16, 2024 - 09:29:13
Django version 4.2.16, using settings 'ScriptRepo.settings'
Starting development server at http://127.0.0.1:26546/
Quit the server with CTRL-BREAK.

Watching for file changes with StatReloader
C:\inetpub\wwwroot\ScriptRepo\ScriptRepo\ScriptRepo\urls.py changed, reloading.
Performing system checks...

System check identified no issues (0 silenced).
November 16, 2024 - 09:31:04
Django version 4.2.16, using settings 'ScriptRepo.settings'
Starting development server at http://127.0.0.1:26546/
Quit the server with CTRL-BREAK.

Watching for file changes with StatReloader
C:\inetpub\wwwroot\ScriptRepo\ScriptRepo\ScriptRepo\settings.py changed, reloading.
Performing system checks...

System check identified no issues (0 silenced).
November 16, 2024 - 09:31:07
Django version 4.2.16, using settings 'ScriptRepo.settings'
Starting development server at http://127.0.0.1:26546/
Quit the server with CTRL-BREAK.

Watching for file changes with StatReloader
[16/Nov/2024 09:31:39] "GET /ScriptRepository/ HTTP/1.1" 200 4943
Not Found: /ScriptRepository/media/profile_pics/ironman_xq2cLIU.jfif
[16/Nov/2024 09:31:39] "GET /ScriptRepository/media/profile_pics/ironman_xq2cLIU.jfif HTTP/1.1" 404 5056
[16/Nov/2024 09:31:40] "GET /ScriptRepository/ HTTP/1.1" 200 4943
[16/Nov/2024 09:31:40] "GET /ScriptRepository/ HTTP/1.1" 200 4943
Not Found: /ScriptRepository/media/profile_pics/ironman_xq2cLIU.jfif
[16/Nov/2024 09:31:40] "GET /ScriptRepository/media/profile_pics/ironman_xq2cLIU.jfif HTTP/1.1" 404 5056
[16/Nov/2024 09:31:41] "GET /ScriptRepository/ HTTP/1.1" 200 4943
[16/Nov/2024 09:31:41] "GET /ScriptRepository/ HTTP/1.1" 200 4943
[16/Nov/2024 09:31:41] "GET /ScriptRepository/ HTTP/1.1" 200 4943
Not Found: /ScriptRepository/media/profile_pics/ironman_xq2cLIU.jfif
[16/Nov/2024 09:31:41] "GET /ScriptRepository/media/profile_pics/ironman_xq2cLIU.jfif HTTP/1.1" 404 5056
C:\inetpub\wwwroot\ScriptRepo\ScriptRepo\ScriptRepo\settings.py changed, reloading.
Performing system checks...

System check identified no issues (0 silenced).
November 16, 2024 - 09:31:29
Django version 4.2.16, using settings 'ScriptRepo.settings'
Starting development server at http://127.0.0.1:26546/
Quit the server with CTRL-BREAK.

Performing system checks...

System check identified no issues (0 silenced).
November 16, 2024 - 09:31:59
Django version 4.2.16, using settings 'ScriptRepo.settings'
Starting development server at http://127.0.0.1:26546/
Quit the server with CTRL-BREAK.

[16/Nov/2024 09:32:22] "GET /ScriptRepository/ HTTP/1.1" 200 4943
[16/Nov/2024 09:32:22] "GET /ScriptRepository/media/profile_pics/ironman_xq2cLIU.jfif HTTP/1.1" 404 179
[16/Nov/2024 09:32:23] "GET /ScriptRepository/ HTTP/1.1" 200 4943
[16/Nov/2024 09:32:23] "GET /ScriptRepository/ HTTP/1.1" 200 4943
[16/Nov/2024 09:32:23] "GET /ScriptRepository/ HTTP/1.1" 200 4943
[16/Nov/2024 09:32:23] "GET /ScriptRepository/ HTTP/1.1" 200 4943
[16/Nov/2024 09:32:24] "GET /ScriptRepository/ HTTP/1.1" 200 4943
[16/Nov/2024 09:32:24] "GET /ScriptRepository/ HTTP/1.1" 200 4943
[16/Nov/2024 09:32:24] "GET /ScriptRepository/media/profile_pics/ironman_xq2cLIU.jfif HTTP/1.1" 404 179
[16/Nov/2024 09:32:25] "GET /ScriptRepository/ HTTP/1.1" 200 4943
[16/Nov/2024 09:32:25] "GET /ScriptRepository/media/profile_pics/ironman_xq2cLIU.jfif HTTP/1.1" 404 179
[16/Nov/2024 09:32:26] "GET /ScriptRepository/ HTTP/1.1" 200 4943
[16/Nov/2024 09:32:26] "GET /ScriptRepository/media/profile_pics/ironman_xq2cLIU.jfif HTTP/1.1" 404 179
[16/Nov/2024 09:32:27] "GET /ScriptRepository/ HTTP/1.1" 200 4943
[16/Nov/2024 09:32:27] "GET /ScriptRepository/media/profile_pics/ironman_xq2cLIU.jfif HTTP/1.1" 404 179
[16/Nov/2024 09:32:27] "GET /ScriptRepository/ HTTP/1.1" 200 4943
[16/Nov/2024 09:32:28] "GET /ScriptRepository/ HTTP/1.1" 200 4943
[16/Nov/2024 09:32:28] "GET /ScriptRepository/media/profile_pics/ironman_xq2cLIU.jfif HTTP/1.1" 404 179
Performing system checks...

System check identified no issues (0 silenced).
November 16, 2024 - 09:32:16
Django version 4.2.16, using settings 'ScriptRepo.settings'
Starting development server at http://127.0.0.1:26546/
Quit the server with CTRL-BREAK.

